Workbook

Sheet Pedidos CardMarket
A1: Order Number | B1: Seller / Buyer | C1: Items | D1: Total Price | E1: Deliver Date | F1: Comentarios | G1: Tipo Operación | H1: TCG
A2: 1285152349 | B2: Distritozero-Bilbao | C2: 4 | D2: 4.41 | E2: 29.06.2026 | F2: Estado: Pagado; Vendedor: Distritozero-Bilbao; Envío repartido: 1.45 EUR | G2: Compra | H2: Magic The Gathering
A3: 1284988797 | B3: Mariluz92 | C3: 1 | D3: 1.7 | E3: 28.06.2026 | F3: Estado: Pagado; Vendedor: Mariluz92; Envío repartido: 1.45 EUR | G3: Compra | H3: Riftbound
A4: 1284988792 | B4: Oscar161 | C4: 1 | D4: 1.65 | E4: 28.06.2026 | F4: Estado: Pagado; Vendedor: Oscar161; Envío repartido: 1.45 EUR | G4: Compra | H4: Riftbound
A5: 1284986651 | B5: CartinhaBrilhante | C5: 16 | D5: 56.49 | E5: 28.06.2026 | F5: Estado: Pagado; Vendedor: CartinhaBrilhante; Envío repartido: 7.06 EUR | G5: Compra | H5: Riftbound
A6: 1284986254 | B6: PulpulFolker | C6: 11 | D6: 47.36 | E6: 28.06.2026 | F6: Estado: Pagado; Vendedor: PulpulFolker; Envío repartido: 7.06 EUR | G6: Compra | H6: Riftbound
A7: 1284983295 | B7: Cyrusi | C7: 2 | D7: 49.48 | E7: 28.06.2026 | F7: Estado: Pagado; Vendedor: Cyrusi; Envío repartido: 7.06 EUR | G7: Compra | H7: Riftbound
A8: 1284982979 | B8: Azgrand | C8: 1 | D8: 16.45 | E8: 28.06.2026 | F8: Estado: Pagado; Vendedor: Azgrand; Envío repartido: 1.45 EUR | G8: Compra | H8: Riftbound
A9: 1284982829 | B9: Canichev | C9: 2 | D9: 3.24 | E9: 28.06.2026 | F9: Estado: Pagado; Vendedor: Canichev; Envío repartido: 1.45 EUR | G9: Compra | H9: Riftbound
A10: 1284982814 | B10: Gorgonas87 | C10: 2 | D10: 2 | E10: 28.06.2026 | F10: Estado: Pagado; Vendedor: Gorgonas87; Envío repartido: 1.45 EUR | G10: Compra | H10: Riftbound
A11: 1284982624 | B11: ManaCore | C11: 2 | D11: 2.89 | E11: 28.06.2026 | F11: Estado: Pagado; Vendedor: ManaCore; Envío repartido: 1.45 EUR | G11: Compra | H11: Riftbound
A12: 1284982290 | B12: Silvela | C12: 5 | D12: 9.45 | E12: 28.06.2026 | F12: Estado: Pagado; Vendedor: Silvela; Envío repartido: 1.45 EUR | G12: Compra | H12: Riftbound
A13: 1284981397 | B13: Moria05 | C13: 8 | D13: 5.24 | E13: 28.06.2026 | F13: Estado: Pagado; Vendedor: Moria05; Envío repartido: 1.45 EUR | G13: Compra | H13: Riftbound
... A267: 1249026814 | B267: Aitorplanchas | C267: 4 | D267: 5.25 | E267: 02.01.2026 | F267: Estado: Recibido; Comprador: Aitorplanchas; Envío repartido: 1.45 EUR | G267: Venta | H267: Magic The Gathering
A268: WA-20260101-03 | B268: Willybizarre | C268: 1 | D268: 330 | E268: 01.01.2026 | F268: Estado: Importado desde Pedidos WhatsApp; origen manual; lineas: 1 | G268: Compra | H268: Magic The Gathering
A269: WA-20260101-02 | B269: Liddia7 | C269: 7 | D269: 31.5 | E269: 01.01.2026 | F269: Estado: Importado desde Pedidos WhatsApp; origen manual; lineas: 2 | G269: Compra | H269: Magic The Gathering
A270: WA-20260101-01 | B270: Bronhy | C270: 2 | D270: 700 | E270: 01.01.2026 | F270: Estado: Importado desde Pedidos WhatsApp; origen manual; lineas: 1 | G270: Compra | H270: Magic The Gathering
A271: 1248886513 | B271: Voldraek | C271: 12 | D271: 8.45 | E271: 01.01.2026 | F271: Estado: Recibido; Comprador: Voldraek; Envío repartido: 2.45 EUR | G271: Venta | H271: Magic The Gathering
A272: 1248630308 | B272: ChaugnarFaugn | C272: 2 | D272: 8.23 | E272: 30.12.2025 | F272: Estado: Recibido; Comprador: ChaugnarFaugn; Envío repartido: 1.33 EUR | G272: Venta | H272: Magic The Gathering
A273: 1248408245 | B273: Arkanum | C273: 2 | D273: 12.23 | E273: 29.12.2025 | F273: Estado: Recibido; Comprador: Arkanum; Envío repartido: 1.33 EUR | G273: Venta | H273: Magic The Gathering
A274: 1248289480 | B274: adriangd | C274: 5 | D274: 2.83 | E274: 28.12.2025 | F274: Estado: Recibido; Comprador: adriangd; Envío repartido: 1.33 EUR | G274: Venta | H274: Magic The Gathering
A275: 1248193531 | B275: salucks | C275: 2 | D275: 4.35 | E275: 28.12.2025 | F275: Estado: Recibido; Comprador: salucks; Envío repartido: 2.45 EUR | G275: Venta | H275: Magic The Gathering
A276: 1248066770 | B276: Javieeh | C276: 2 | D276: 9.78 | E276: 27.12.2025 | F276: Estado: Recibido; Comprador: Javieeh; Envío repartido: 1.33 EUR | G276: Venta | H276: Magic The Gathering
A277: 1247810200 | B277: enrico3547 | C277: 4 | D277: 55.4 | E277: 25.12.2025 | F277: Estado: Recibido; Comprador: enrico3547; Envío repartido: 7.60 EUR | G277: Venta | H277: Magic The Gathering
A278: 1247673365 | B278: Vitosellmagic | C278: 3 | D278: 25.18 | E278: 24.12.2025 | F278: Estado: Enviado; Vendedor: Vitosellmagic; Envío repartido: 1.33 EUR | G278: Compra | H278: Magic The Gathering
A279: 1247489911 | B279: Zeross | C279: 1 | D279: 4.4 | E279: 23.12.2025 | F279: Estado: Recibido; Comprador: Zeross; Envío repartido: 2.45 EUR | G279: Venta | H279: Magic The Gathering
A280: 1247478896 | B280: Mikota | C280: 1 | D280: 5.28 | E280: 23.12.2025 | F280: Estado: Recibido; Comprador: Mikota; Envío repartido: 1.33 EUR | G280: Venta | H280: Magic The Gathering
A281: 1247458671 | B281: Espartano88 | C281: 4 | D281: 12.53 | E281: 23.12.2025 | F281: Estado: Cancelado; Comprador: Espartano88; Envío repartido: 1.33 EUR | G281: Cancelado | H281: Magic The Gathering
A282: 1247427520 | B282: Larguiruncio | C282: 1 | D282: 1.58 | E282: 22.12.2025 | F282: Estado: Recibido; Comprador: Larguiruncio; Envío repartido: 1.33 EUR | G282: Venta | H282: Magic The Gathering
... A290: 1247229759 | B290: daktylus75 | C290: 4 | D290: 13.25 | E290: 21.12.2025 | F290: Estado: Recibido; Comprador: daktylus75; Envío repartido: 2.45 EUR | G290: Venta | H290: Magic The Gathering
A291: WA-20251220-01 | B291: 34628270693 | C291: 1 | D291: 310 | E291: 20.12.2025 | F291: Estado: Importado desde Pedidos WhatsApp; origen manual; lineas: 1 | G291: Compra | H291: Magic The Gathering
A292: 1247020450 | B292: Cuatrolo | C292: 1 | D292: 3.28 | E292: 19.12.2025 | F292: Estado: Recibido; Comprador: Cuatrolo; Envío repartido: 1.33 EUR | G292: Venta | H292: Magic The Gathering
A293: 1246809442 | B293: Racato | C293: 4 | D293: 87.4 | E293: 18.12.2025 | F293: Estado: Recibido; Comprador: Racato; Envío repartido: 7.60 EUR | G293: Venta | H293: Magic The Gathering
A294: 1246782050 | B294: Devian-Magic-Cards | C294: 5 | D294: 47.62 | E294: 18.12.2025 | F294: Estado: Enviado; Vendedor: Devian-Magic-Cards; Envío repartido: 5.93 EUR | G294: Compra | H294: Magic The Gathering
A295: 1246778711 | B295: botusfetus | C295: 4 | D295: 5.13 | E295: 18.12.2025 | F295: Estado: Recibido; Comprador: botusfetus; Envío repartido: 1.33 EUR | G295: Venta | H295: Magic The Gathering
A296: 1246502519 | B296: Aleixescurabello | C296: 1 | D296: 1.83 | E296: 16.12.2025 | F296: Estado: Recibido; Comprador: Aleixescurabello; Envío repartido: 1.33 EUR | G296: Venta | H296: Magic The Gathering
A297: 1246390151 | B297: Seath93 | C297: 1 | D297: 335.5 | E297: 15.12.2025 | F297: Estado: Enviado; Vendedor: Seath93; Envío repartido: 34.00 EUR | G297: Compra | H297: Magic The Gathering
A298: 1246389998 | B298: Rodrigbli | C298: 1 | D298: 1.53 | E298: 15.12.2025 | F298: Estado: Enviado; Vendedor: Rodrigbli; Envío repartido: 1.33 EUR | G298: Compra | H298: Magic The Gathering
A299: 1246130252 | B299: Devian-Magic-Cards | C299: 5 | D299: 47.62 | E299: 14.12.2025 | F299: Estado: Cancelado; Vendedor: Devian-Magic-Cards; Envío repartido: 5.93 EUR | G299: Cancelado | H299: Magic The Gathering
A300: 1246129625 | B300: Distritozero-San | C300: 3 | D300: 21 | E300: 14.12.2025 | F300: Estado: Cancelado en CardMarket; recogido en mano; Vendedor: Distritozero-San; Envío eliminado por recogida en mano: 5.50 EUR | G300: Cancelado | H300: Magic The Gathering
...

Sheet Colección
A1: Order Number | B1: Mes | C1: Año | D1: Date | E1: Seller / Buyer | F1: Card Name | G1: Edition | H1: Playset | I1: Language | J1: Unit Price | K1: Quantity | L1: Total | M1: Tipo Operación | N1: Precio de venta | O1: TCG
A2: 1164742270 | B2: Julio | C2: 2024 | D2: 45490.423 | E2: Knowny | F2: Phlage, Titan of Fire's Fury | G2: Modern Horizons 3 | H2: No | I2: Inglés | J2: 51.773333 | K2: 3 | L2: =J2*K2 -> 155.32 | M2: Venta | N2: 155.32 | O2: Magic The Gathering
A3: WA-20241001-01 | B3: Octubre | C3: 2024 | D3: 45566 | E3: 34633956985 | F3: Ocelot Pride | G3: Modern Horizons 3 | H3: Si | I3: Inglés | J3: 35.8175 | K3: 4 | L3: =J3*K3 -> 143.27 | M3: Venta | N3: 143.27 | O3: Magic The Gathering
A4: 1120143415 | B4: Julio | C4: 2023 | D4: 45134.502 | E4: NeverlandMTG | F4: Grief [Playset] | G4: Modern Horizons 2 | H4: No | I4: Inglés | J4: 130.28 | K4: 1 | L4: =J4*K4 -> 130.28 | M4: Venta | N4: 130.28 | O4: Magic The Gathering
A5: 1181893231 | B5: Noviembre | C5: 2024 | D5: 45626.486 | E5: Torkok | F5: Tamiyo, Inquisitive Student // Tamiyo, Seasoned Scholar | G5: Modern Horizons 2: Extras | H5: Si | I5: Inglés | J5: 31.767415 | K5: 4 | L5: =J5*K5 -> 127.06966 | M5: Venta | N5: 127.06966 | O5: Magic The Gathering
A6: 1208867327 | B6: Abril | C6: 2025 | D6: 45775.863 | E6: tobinono | F6: Parallax Wave | G6: Nemesis | H6: Si | I6: Japonés | J6: 29.85 | K6: 4 | L6: =J6*K6 -> 119.4 | M6: Venta | N6: 119.4 | O6: Magic The Gathering
A7: 1164075103 | B7: Julio | C7: 2024 | D7: 45475.811 | E7: rafa-1993-magic | F7: Atraxa, Grand Unifier [Playset] | G7: Phyrexia: All Will Be One | H7: No | I7: Inglés | J7: 105.39928 | K7: 1 | L7: =J7*K7 -> 105.39928 | M7: Venta | N7: 105.39928 | O7: Magic The Gathering
A8: 1164617239 | B8: Julio | C8: 2024 | D8: 45486.496 | E8: Oyea2000Hacha | F8: Phlage, Titan of Fire's Fury | G8: Modern Horizons 3 | H8: No | I8: Inglés | J8: 52.152551 | K8: 2 | L8: =J8*K8 -> 104.3051 | M8: Venta | N8: 104.3051 | O8: Magic The Gathering
A9: CVSALE-1121120101-01 | B9: Julio | C9: 2023 | D9: 45133.373 | E9: Venta asociada sin pedido identificado | F9: Ragavan, Nimble Pilferer | G9: Modern Horizons 2 | H9: Si | I9: Inglés | J9: 95.39 | K9: 1 | L9: =J9*K9 -> 95.39 | M9: Venta | N9: 95.39 | O9: Magic The Gathering
A10: 1179893768 | B10: Octubre | C10: 2024 | D10: 45596.443 | E10: Veilanof | F10: Ajani, Nacatl Pariah // Ajani, Nacatl Avenger | G10: Modern Horizons 3: Extras | H10: Si | I10: Inglés | J10: 22.3175 | K10: 4 | L10: =J10*K10 -> 89.27 | M10: Venta | N10: 89.27 | O10: Magic The Gathering
A11: 1284601698 | B11: Junio | C11: 2026 | D11: 46199.732 | E11: ElCige | F11: Snapcaster Mage | G11: Innistrad Remastered: Extras | H11: Si | I11: Japonés | J11: 21.96 | K11: 4 | L11: =J11*K11 -> 87.84 | M11: Venta | N11: 87.84 | O11: Magic The Gathering
A12: 1246809442 | B12: Diciembre | C12: 2025 | D12: 46020.428 | E12: Racato | F12: Riverpyre Verge | G12: Aetherdrift: Extras | H12: Si | I12: Inglés | J12: 21.85 | K12: 4 | L12: =J12*K12 -> 87.4 | M12: Venta | N12: 87.4 | O12: Magic The Gathering
A13: 1163758975 | B13: Julio | C13: 2024 | D13: 45476.34 | E13: davolcu | F13: Agatha's Soul Cauldron | G13: Wilds of Eldraine | H13: No | I13: Inglés | J13: 42.685 | K13: 2 | L13: =J13*K13 -> 85.37 | M13: Venta | N13: 85.37 | O13: Magic The Gathering
A14: 1164216706 | B14: Julio | C14: 2024 | D14: 45476.773 | E14: TheGoe | F14: Misty Rainforest [Playset] | G14: Modern Horizons 2 | H14: No | I14: Inglés | J14: 82.25 | K14: 1 | L14: =J14*K14 -> 82.25 | M14: Venta | N14: 82.25 | O14: Magic The Gathering
A15: 1146287863 | B15: Febrero | C15: 2024 | D15: 45345.518 | E15: kuerpo | F15: Sheoldred, the Apocalypse | G15: Dominaria United | H15: No | I15: Español | J15: 80.42 | K15: 1 | L15: =J15*K15 -> 80.42 | M15: Venta | N15: 80.42 | O15: Magic The Gathering
A16: 1178792325 | B16: Octubre | C16: 2024 | D16: 45582.813 | E16: SrBau | F16: Psychic Frog | G16: Modern Horizons 3 | H16: Si | I16: Inglés | J16: 17.3175 | K16: 4 | L16: =J16*K16 -> 69.27 | M16: Venta | N16: 69.27 | O16: Magic The Gathering
A17: WA-20250708-01 | B17: Julio | C17: 2025 | D17: 45846 | E17: 34653388331 | F17: Ravenous Baloth | G17: Onslaught | H17: No | I17: Japonés | J17: 17 | K17: 4 | L17: =J17*K17 -> 68 | M17: Venta | N17: 68 | O17: Magic The Gathering
A18: 1236601962 | B18: Octubre | C18: 2025 | D18: 45959.634 | E18: Kacon | F18: Starting Town | G18: Magic: The Gathering - FINAL FANTASY | H18: Si | I18: Inglés | J18: 16.8 | K18: 4 | L18: =J18*K18 -> 67.2 | M18: Venta | N18: 67.2 | O18: Magic The Gathering
A19: 1198292265 | B19: Febrero | C19: 2025 | D19: 45715.351 | E19: safetronik1985 | F19: Overlord of the Hauntwoods | G19: Duskmourn: House of Horror | H19: Si | I19: Inglés | J19: 16.3825 | K19: 4 | L19: =J19*K19 -> 65.53 | M19: Venta | N19: 65.53 | O19: Magic The Gathering
A20: 1163978024 | B20: Julio | C20: 2024 | D20: 45475.309 | E20: Macufa | F20: Arid Mesa [Playset] | G20: Modern Horizons 2 | H20: No | I20: Inglés | J20: 65.42 | K20: 1 | L20: =J20*K20 -> 65.42 | M20: Venta | N20: 65.42 | O20: Magic The Gathering
A21: 1162835755 | B21: Julio | C21: 2024 | D21: 45489.051 | E21: Noeperez | F21: Flooded Strand | G21: Khans of Tarkir | H21: Si | I21: Español | J21: 16.3175 | K21: 4 | L21: =J21*K21 -> 65.27 | M21: Venta | N21: 65.27 | O21: Magic The Gathering
A22: 1240414115 | B22: Noviembre | C22: 2025 | D22: 45974.51 | E22: Lorme87 | F22: Ulamog, the Defiler | G22: Modern Horizons 3 | H22: No | I22: Japonés | J22: 20.926667 | K22: 3 | L22: =J22*K22 -> 62.78 | M22: Venta | N22: 62.78 | O22: Magic The Gathering
A23: 1255482037 | B23: Febrero | C23: 2026 | D23: 46062.577 | E23: Kenoven | F23: Monument to Endurance | G23: Aetherdrift: Extras | H23: Si | I23: Inglés | J23: 15.5575 | K23: 4 | L23: =J23*K23 -> 62.23 | M23: Venta | N23: 62.23 | O23: Magic The Gathering
A24: 1231603567 | B24: Septiembre | C24: 2025 | D24: 45925.419 | E24: dacamcue | F24: Sheoldred, the Apocalypse | G24: Dominaria United | H24: No | I24: Español | J24: 60.88 | K24: 1 | L24: =J24*K24 -> 60.88 | M24: Venta | N24: 60.88 | O24: Magic The Gathering
A25: 1164973766 | B25: Julio | C25: 2024 | D25: 45482.461 | E25: danicsb | F25: Verdant Catacombs [Playset] | G25: Zendikar | H25: No | I25: Español | J25: 55.42 | K25: 1 | L25: =J25*K25 -> 55.42 | M25: Venta | N25: 55.42 | O25: Magic The Gathering
A26: 1163688955 | B26: Julio | C26: 2024 | D26: 45475.777 | E26: Metropolis-Center | F26: Shuko [Playset] | G26: Betrayers of Kamigawa | H26: No | I26: Español | J26: 55.42 | K26: 1 | L26: =J26*K26 -> 55.42 | M26: Venta | N26: 55.42 | O26: Magic The Gathering
A27: 1247810200 | B27: Enero | C27: 2026 | D27: 46028.597 | E27: enrico3547 | F27: Stormchaser's Talent | G27: Bloomburrow | H27: Si | I27: Inglés | J27: 13.85 | K27: 4 | L27: =J27*K27 -> 55.4 | M27: Venta | N27: 55.4 | O27: Magic The Gathering
A28: CVSALE-1142556696-01 | B28: Enero | C28: 2024 | D28: 45311.474 | E28: Venta asociada sin pedido identificado | F28: Scalding Tarn | G28: Modern Horizons 2 | H28: No | I28: Inglés | J28: 27.21 | K28: 2 | L28: =J28*K28 -> 54.42 | M28: Venta | N28: 54.42 | O28: Magic The Gathering
A29: 1166492703 | B29: Julio | C29: 2024 | D29: 45494.41 | E29: hotcoffeegg | F29: Steam Vents [Playset] | G29: Ravnica Remastered | H29: No | I29: Inglés | J29: 54.127775 | K29: 1 | L29: =J29*K29 -> 54.127775 | M29: Venta | N29: 54.127775 | O29: Magic The Gathering
A30: 1188500052 | B30: Enero | C30: 2025 | D30: 45664.515 | E30: Vintar | F30: The Meathook Massacre (V.2) | G30: Innistrad: Midnight Hunt: Promos | H30: No | I30: Inglés | J30: 26.524307 | K30: 2 | L30: =J30*K30 -> 53.048615 | M30: Venta | N30: 53.048615 | O30: Magic The Gathering
A31: 1164108421 | B31: Julio | C31: 2024 | D31: 45475.957 | E31: WORKSHOP12 | F31: Marsh Flats [Playset] | G31: Modern Horizons 2 | H31: No | I31: Inglés | J31: 52.829099 | K31: 1 | L31: =J31*K31 -> 52.829099 | M31: Venta | N31: 52.829099 | O31: Magic The Gathering
A32: 1176843547 | B32: Octubre | C32: 2024 | D32: 45576.409 | E32: J4ceBeleren | F32: Orcish Bowmasters | G32: The Lord of the Rings: Tales of Middle-earth | H32: No | I32: Inglés | J32: 52.25 | K32: 1 | L32: =J32*K32 -> 52.25 | M32: Venta | N32: 52.25 | O32: Magic The Gathering
A33: 1119858259 | B33: Julio | C33: 2023 | D33: 45129.326 | E33: GnarChikito | F33: Orcish Bowmasters | G33: The Lord of the Rings: Tales of Middle-earth | H33: No | I33: Inglés | J33: 49.15427 | K33: 1 | L33: =J33*K33 -> 49.15427 | M33: Venta | N33: 49.15427 | O33: Magic The Gathering
A34: CVSALE-1145214768-01 | B34: Febrero | C34: 2024 | D34: 45332.82 | E34: Venta asociada sin pedido identificado | F34: Breeding Pool | G34: Gatecrash | H34: No | I34: Inglés | J34: 47.62 | K34: 1 | L34: =J34*K34 -> 47.62 | M34: Venta | N34: 47.62 | O34: Magic The Gathering
A35: 1164108421 | B35: Julio | C35: 2024 | D35: 45475.957 | E35: WORKSHOP12 | F35: Goryo's Vengeance [Playset] | G35: Betrayers of Kamigawa | H35: No | I35: Español | J35: 47.540901 | K35: 1 | L35: =J35*K35 -> 47.540901 | M35: Venta | N35: 47.540901 | O35: Magic The Gathering
A36: 1166492703 | B36: Julio | C36: 2024 | D36: 45499.705 | E36: hotcoffeegg | F36: Ledger Shredder | G36: Streets of New Capenna: Extras | H36: No | I36: Inglés | J36: 15.808095 | K36: 3 | L36: =J36*K36 -> 47.424286 | M36: Venta | N36: 47.424286 | O36: Magic The Gathering
A37: 1165660431 | B37: Julio | C37: 2024 | D37: 45492.343 | E37: Jesval | F37: Phlage, Titan of Fire's Fury | G37: Modern Horizons 3 | H37: No | I37: Inglés | J37: 47.42 | K37: 1 | L37: =J37*K37 -> 47.42 | M37: Venta | N37: 47.42 | O37: Magic The Gathering
A38: 1119858259 | B38: Julio | C38: 2023 | D38: 45129.326 | E38: GnarChikito | F38: Orcish Bowmasters | G38: The Lord of the Rings: Tales of Middle-earth | H38: No | I38: Inglés | J38: 47.040108 | K38: 1 | L38: =J38*K38 -> 47.040108 | M38: Venta | N38: 47.040108 | O38: Magic The Gathering
A39: CVSALE-1130277526-01 | B39: Octubre | C39: 2023 | D39: 45208.902 | E39: Venta asociada sin pedido identificado | F39: Sacred Foundry | G39: Ravnica: City of Guilds | H39: No | I39: Inglés | J39: 22.92 | K39: 2 | L39: =J39*K39 -> 45.84 | M39: Venta | N39: 45.84 | O39: Magic The Gathering
A40: 1157257374 | B40: Mayo | C40: 2024 | D40: 45425.982 | E40: Kalashju | F40: Leyline of the Guildpact [Playset] | G40: Murders at Karlov Manor | H40: No | I40: Inglés | J40: 45.42 | K40: 1 | L40: =J40*K40 -> 45.42 | M40: Venta | N40: 45.42 | O40: Magic The Gathering
...

Sheet Tablas
A1: Tipo Operación | B1: Compra | D1: Etiquetas de fila | E1: Suma de Total | G1: Tipo Operación | H1: Compra | L1: Tipo Operación | M1: Compra | O1: Tipo Operación | P1: Compra
D2: Compra | E2: 39622.374
A3: Etiquetas de fila | B3: Suma de Total | D3: Venta | E3: 7217.9134 | G3: Etiquetas de fila | H3: Suma de Total | I3: Suma de Quantity | L3: Etiquetas de fila | M3: Suma de Total | O3: Etiquetas de fila | P3: Suma de Total
A4: 2022 | B4: 3852.76 | D4: (en blanco) | G4: Modern Horizons 2: Extras | H4: 2246.7577 | I4: 145 | L4: City of Traitors | M4: 1293.97 | O4: Magic The Gathering | P4: 35620.341
A5: 2023 | B5: 6353.4336 | D5: Total general | E5: 46840.288 | G5: Unleashed | H5: 1759.3655 | I5: 163 | L5: Serra's Sanctum | M5: 1030 | O5: One Piece | P5: 334.62386
A6: 2024 | B6: 10771.94 | G6: Modern Horizons 3 | H6: 1489.2334 | I6: 265 | L6: Collector Booster Box The Hobbit | M6: 899.9 | O6: Riftbound | P6: 3667.41
A7: 2025 | B7: 10887.041 | G7: Exodus | H7: 1327.3305 | I7: 9 | L7: Underground Sea | M7: 600 | O7: Total general | P7: 39622.374
A8: 2026 | B8: 7757.2 | G8: Modern Horizons 3: Extras | H8: 1316.4214 | I8: 123 | L8: Unleashed Booster Box Case (6x) | M8: 590
A9: Total general | B9: 39622.374 | G9: The Lord of the Rings: Tales of Middle-earth | H9: 1260.9508 | I9: 266 | L9: Scrubland | M9: 425
G10: Urza's Saga | H10: 1128.7762 | I10: 71 | L10: Flooded Strand | M10: 393.35598
G11: Revised | H11: 1025 | I11: 3 | L11: Vivi Ornitier (V.1) | M11: 324.79
G12: Onslaught | H12: 1002.0291 | I12: 39 | L12: Wooded Foothills | M12: 323.41573
G13: Modern Horizons 2 | H13: 994.97726 | I13: 173 | L13: Chrome Mox | M13: 315.49
G14: The Hobbit | H14: 899.9 | I14: 2 | L14: Mox Opal | M14: 296.72727
G15: Fourth Edition: Black Bordered | H15: 737.84364 | I15: 103 | L15: Orcish Bowmasters | M15: 272.65
G16: Spiritforged | H16: 683.23768 | I16: 135 | L16: Bloodstained Mire | M16: 268.37573
G17: Origins | H17: 643.5869 | I17: 121 | L17: Agatha's Soul Cauldron | M17: 266.25
G18: Time Spiral Remastered: Extras | H18: 571.77355 | I18: 113 | L18: Arcane Box Set | M18: 237.57917
G19: Origins: Promos | H19: 554.98917 | I19: 6 | L19: Worlds Bundle 2025 | M19: 236
G20: Double Masters 2022: Extras | H20: 459.8881 | I20: 66 | L20: Ocelot Pride (V.1) | M20: 232.96279
G21: Modern Horizons | H21: 457.08676 | I21: 97 | L21: Fury [Playset] | M21: 223.7
... G34: Total general | H34: 22939.997 | I34: 2332 | L34: Scalding Tarn (V.1) | M34: 174.1082
L35: Misty Rainforest (V.1) | M35: 171.25565
L36: Nethergoyf | M36: 167.6
L37: Teferi, Time Raveler | M37: 162.89944
L38: Prismatic Vista (V.1) | M38: 160.55
L39: Wrenn and Six (V.1) | M39: 154.05
L40: Amulet of Vigor | M40: 152.69
L41: Baited Hook | M41: 150.63475
L42: Stifle | M42: 150
L43: Psychic Frog (V.1) | M43: 149.30258
L44: Subtlety | M44: 147.06026
L45: Sephiroth, Fabled SOLDIER // Sephiroth, One-Winged Angel (V.1) | M45: 146.84
L46: Windswept Heath [Playset] | M46: 145.47
... L54: Total general | M54: 13619.969

Sheet Graficos Legacy
A1: Dashboard actualizado con Compra y Venta separadas
A3: Gasto total mensual | J3: Resumen por TCG
A4: Mes | B4: Suma de Total | E4: Lineas coleccion | F4: =COUNTA(Colección!$A$2:$A$10001) -> 3857 | J4: TCG | K4: Quantity compra | L4: Total compra | M4: Precio venta
A5: =YEAR(DATE(2026,6,1))&"-"&RIGHT("0"&MONTH(DATE(2026,6,1)),2)&" "&CHOOSE(MONTH(DATE(2026,6,1)),"enero","febrero","marzo","abril","mayo","junio","julio","agosto","septiembre","octubre","noviembre","diciembre") -> 2026-06 junio | B5: =SUMIFS(Colección!$L$2:$L$10001,Colección!$M$2:$M$10001,"Compra",Colección!$D$2:$D$10001,">="&DATE(2026,6,1),Colección!$D$2:$D$10001,"<"&DATE(2026,7,1)) -> 3510.83 | E5: Lineas Compra | F5: =COUNTIF(Colección!$M$2:$M$10001,"Compra") -> 3287 | J5: ="Magic The Gathering" -> Magic The Gathering | K5: =IF($J5="","",SUMIFS(Colección!$K$2:$K$10001,Colección!$O$2:$O$10001,$J5,Colección!$M$2:$M$10001,"Compra")) -> 6337 | L5: =IF($J5="","",SUMIFS(Colección!$L$2:$L$10001,Colección!$O$2:$O$10001,$J5,Colección!$M$2:$M$10001,"Compra")) -> 35680.341 | M5: =IF($J5="","",SUMIFS(Colección!$N$2:$N$10001,Colección!$O$2:$O$10001,$J5,Colección!$M$2:$M$10001,"Venta")) -> 7222.779
A6: =YEAR(DATE(2026,5,1))&"-"&RIGHT("0"&MONTH(DATE(2026,5,1)),2)&" "&CHOOSE(MONTH(DATE(2026,5,1)),"enero","febrero","marzo","abril","mayo","junio","julio","agosto","septiembre","octubre","noviembre","diciembre") -> 2026-05 mayo | B6: =SUMIFS(Colección!$L$2:$L$10001,Colección!$M$2:$M$10001,"Compra",Colección!$D$2:$D$10001,">="&DATE(2026,5,1),Colección!$D$2:$D$10001,"<"&DATE(2026,6,1)) -> 1230.3 | E6: Lineas Venta | F6: =COUNTIF(Colección!$M$2:$M$10001,"Venta") -> 570 | J6: ="Riftbound" -> Riftbound | K6: =IF($J6="","",SUMIFS(Colección!$K$2:$K$10001,Colección!$O$2:$O$10001,$J6,Colección!$M$2:$M$10001,"Compra")) -> 429 | L6: =IF($J6="","",SUMIFS(Colección!$L$2:$L$10001,Colección!$O$2:$O$10001,$J6,Colección!$M$2:$M$10001,"Compra")) -> 3667.41 | M6: =IF($J6="","",SUMIFS(Colección!$N$2:$N$10001,Colección!$O$2:$O$10001,$J6,Colección!$M$2:$M$10001,"Venta")) -> 0
A7: =YEAR(DATE(2026,4,1))&"-"&RIGHT("0"&MONTH(DATE(2026,4,1)),2)&" "&CHOOSE(MONTH(DATE(2026,4,1)),"enero","febrero","marzo","abril","mayo","junio","julio","agosto","septiembre","octubre","noviembre","diciembre") -> 2026-04 abril | B7: =SUMIFS(Colección!$L$2:$L$10001,Colección!$M$2:$M$10001,"Compra",Colección!$D$2:$D$10001,">="&DATE(2026,4,1),Colección!$D$2:$D$10001,"<"&DATE(2026,5,1)) -> 27.76 | E7: Gasto compra total | F7: =SUMIFS(Colección!$L$2:$L$10001,Colección!$M$2:$M$10001,"Compra") -> 39682.374 | J7: ="One Piece" -> One Piece | K7: =IF($J7="","",SUMIFS(Colección!$K$2:$K$10001,Colección!$O$2:$O$10001,$J7,Colección!$M$2:$M$10001,"Compra")) -> 373 | L7: =IF($J7="","",SUMIFS(Colección!$L$2:$L$10001,Colección!$O$2:$O$10001,$J7,Colección!$M$2:$M$10001,"Compra")) -> 334.62386 | M7: =IF($J7="","",SUMIFS(Colección!$N$2:$N$10001,Colección!$O$2:$O$10001,$J7,Colección!$M$2:$M$10001,"Venta")) -> 19.47
A8: =YEAR(DATE(2026,3,1))&"-"&RIGHT("0"&MONTH(DATE(2026,3,1)),2)&" "&CHOOSE(MONTH(DATE(2026,3,1)),"enero","febrero","marzo","abril","mayo","junio","julio","agosto","septiembre","octubre","noviembre","diciembre") -> 2026-03 marzo | B8: =SUMIFS(Colección!$L$2:$L$10001,Colección!$M$2:$M$10001,"Compra",Colección!$D$2:$D$10001,">="&DATE(2026,3,1),Colección!$D$2:$D$10001,"<"&DATE(2026,4,1)) -> 241.54 | E8: Importe venta total | F8: =SUMIFS(Colección!$N$2:$N$10001,Colección!$M$2:$M$10001,"Venta") -> 7242.249
A9: =YEAR(DATE(2026,2,1))&"-"&RIGHT("0"&MONTH(DATE(2026,2,1)),2)&" "&CHOOSE(MONTH(DATE(2026,2,1)),"enero","febrero","marzo","abril","mayo","junio","julio","agosto","septiembre","octubre","noviembre","diciembre") -> 2026-02 febrero | B9: =SUMIFS(Colección!$L$2:$L$10001,Colección!$M$2:$M$10001,"Compra",Colección!$D$2:$D$10001,">="&DATE(2026,2,1),Colección!$D$2:$D$10001,"<"&DATE(2026,3,1)) -> 358.21 | E9: Lineas Cancelado | F9: =COUNTIF(Colección!$M$2:$M$10001,"Cancelado") -> 0
A10: =YEAR(DATE(2026,1,1))&"-"&RIGHT("0"&MONTH(DATE(2026,1,1)),2)&" "&CHOOSE(MONTH(DATE(2026,1,1)),"enero","febrero","marzo","abril","mayo","junio","julio","agosto","septiembre","octubre","noviembre","diciembre") -> 2026-01 enero | B10: =SUMIFS(Colección!$L$2:$L$10001,Colección!$M$2:$M$10001,"Compra",Colección!$D$2:$D$10001,">="&DATE(2026,1,1),Colección!$D$2:$D$10001,"<"&DATE(2026,2,1)) -> 2448.56
A11: =YEAR(DATE(2025,12,1))&"-"&RIGHT("0"&MONTH(DATE(2025,12,1)),2)&" "&CHOOSE(MONTH(DATE(2025,12,1)),"enero","febrero","marzo","abril","mayo","junio","julio","agosto","septiembre","octubre","noviembre","diciembre") -> 2025-12 diciembre | B11: =SUMIFS(Colección!$L$2:$L$10001,Colección!$M$2:$M$10001,"Compra",Colección!$D$2:$D$10001,">="&DATE(2025,12,1),Colección!$D$2:$D$10001,"<"&DATE(2025,13,1)) -> 1465.13
A12: =YEAR(DATE(2025,11,1))&"-"&RIGHT("0"&MONTH(DATE(2025,11,1)),2)&" "&CHOOSE(MONTH(DATE(2025,11,1)),"enero","febrero","marzo","abril","mayo","junio","julio","agosto","septiembre","octubre","noviembre","diciembre") -> 2025-11 noviembre | B12: =SUMIFS(Colección!$L$2:$L$10001,Colección!$M$2:$M$10001,"Compra",Colección!$D$2:$D$10001,">="&DATE(2025,11,1),Colección!$D$2:$D$10001,"<"&DATE(2025,12,1)) -> 554.11
A13: =YEAR(DATE(2025,10,1))&"-"&RIGHT("0"&MONTH(DATE(2025,10,1)),2)&" "&CHOOSE(MONTH(DATE(2025,10,1)),"enero","febrero","marzo","abril","mayo","junio","julio","agosto","septiembre","octubre","noviembre","diciembre") -> 2025-10 octubre | B13: =SUMIFS(Colección!$L$2:$L$10001,Colección!$M$2:$M$10001,"Compra",Colección!$D$2:$D$10001,">="&DATE(2025,10,1),Colección!$D$2:$D$10001,"<"&DATE(2025,11,1)) -> 456.03
A14: =YEAR(DATE(2025,9,1))&"-"&RIGHT("0"&MONTH(DATE(2025,9,1)),2)&" "&CHOOSE(MONTH(DATE(2025,9,1)),"enero","febrero","marzo","abril","mayo","junio","julio","agosto","septiembre","octubre","noviembre","diciembre") -> 2025-09 septiembre | B14: =SUMIFS(Colección!$L$2:$L$10001,Colección!$M$2:$M$10001,"Compra",Colección!$D$2:$D$10001,">="&DATE(2025,9,1),Colección!$D$2:$D$10001,"<"&DATE(2025,10,1)) -> 195.62
A15: =YEAR(DATE(2025,8,1))&"-"&RIGHT("0"&MONTH(DATE(2025,8,1)),2)&" "&CHOOSE(MONTH(DATE(2025,8,1)),"enero","febrero","marzo","abril","mayo","junio","julio","agosto","septiembre","octubre","noviembre","diciembre") -> 2025-08 agosto | B15: =SUMIFS(Colección!$L$2:$L$10001,Colección!$M$2:$M$10001,"Compra",Colección!$D$2:$D$10001,">="&DATE(2025,8,1),Colección!$D$2:$D$10001,"<"&DATE(2025,9,1)) -> 243.64
A16: =YEAR(DATE(2025,7,1))&"-"&RIGHT("0"&MONTH(DATE(2025,7,1)),2)&" "&CHOOSE(MONTH(DATE(2025,7,1)),"enero","febrero","marzo","abril","mayo","junio","julio","agosto","septiembre","octubre","noviembre","diciembre") -> 2025-07 julio | B16: =SUMIFS(Colección!$L$2:$L$10001,Colección!$M$2:$M$10001,"Compra",Colección!$D$2:$D$10001,">="&DATE(2025,7,1),Colección!$D$2:$D$10001,"<"&DATE(2025,8,1)) -> 739.23
A17: =YEAR(DATE(2025,6,1))&"-"&RIGHT("0"&MONTH(DATE(2025,6,1)),2)&" "&CHOOSE(MONTH(DATE(2025,6,1)),"enero","febrero","marzo","abril","mayo","junio","julio","agosto","septiembre","octubre","noviembre","diciembre") -> 2025-06 junio | B17: =SUMIFS(Colección!$L$2:$L$10001,Colección!$M$2:$M$10001,"Compra",Colección!$D$2:$D$10001,">="&DATE(2025,6,1),Colección!$D$2:$D$10001,"<"&DATE(2025,7,1)) -> 701.66 | J17: Resumen Compra/Venta
A18: =YEAR(DATE(2025,5,1))&"-"&RIGHT("0"&MONTH(DATE(2025,5,1)),2)&" "&CHOOSE(MONTH(DATE(2025,5,1)),"enero","febrero","marzo","abril","mayo","junio","julio","agosto","septiembre","octubre","noviembre","diciembre") -> 2025-05 mayo | B18: =SUMIFS(Colección!$L$2:$L$10001,Colección!$M$2:$M$10001,"Compra",Colección!$D$2:$D$10001,">="&DATE(2025,5,1),Colección!$D$2:$D$10001,"<"&DATE(2025,6,1)) -> 490.35 | J18: Tipo Operacion | K18: Suma Quantity | L18: Total compra | M18: Precio venta
A19: =YEAR(DATE(2025,4,1))&"-"&RIGHT("0"&MONTH(DATE(2025,4,1)),2)&" "&CHOOSE(MONTH(DATE(2025,4,1)),"enero","febrero","marzo","abril","mayo","junio","julio","agosto","septiembre","octubre","noviembre","diciembre") -> 2025-04 abril | B19: =SUMIFS(Colección!$L$2:$L$10001,Colección!$M$2:$M$10001,"Compra",Colección!$D$2:$D$10001,">="&DATE(2025,4,1),Colección!$D$2:$D$10001,"<"&DATE(2025,5,1)) -> 2333.71 | J19: ="Compra" -> Compra | K19: =SUMIFS(Colección!$K$2:$K$10001,Colección!$M$2:$M$10001,$J19) -> 7139 | L19: =IF($J19="Compra",SUMIFS(Colección!$L$2:$L$10001,Colección!$M$2:$M$10001,$J19),0) -> 39682.374 | M19: =IF($J19="Venta",SUMIFS(Colección!$N$2:$N$10001,Colección!$M$2:$M$10001,$J19),0) -> 0
A20: =YEAR(DATE(2025,3,1))&"-"&RIGHT("0"&MONTH(DATE(2025,3,1)),2)&" "&CHOOSE(MONTH(DATE(2025,3,1)),"enero","febrero","marzo","abril","mayo","junio","julio","agosto","septiembre","octubre","noviembre","diciembre") -> 2025-03 marzo | B20: =SUMIFS(Colección!$L$2:$L$10001,Colección!$M$2:$M$10001,"Compra",Colección!$D$2:$D$10001,">="&DATE(2025,3,1),Colección!$D$2:$D$10001,"<"&DATE(2025,4,1)) -> 2207.0009 | J20: ="Venta" -> Venta | K20: =SUMIFS(Colección!$K$2:$K$10001,Colección!$M$2:$M$10001,$J20) -> 1073 | L20: =IF($J20="Compra",SUMIFS(Colección!$L$2:$L$10001,Colección!$M$2:$M$10001,$J20),0) -> 0 | M20: =IF($J20="Venta",SUMIFS(Colección!$N$2:$N$10001,Colección!$M$2:$M$10001,$J20),0) -> 7242.249
A21: =YEAR(DATE(2025,2,1))&"-"&RIGHT("0"&MONTH(DATE(2025,2,1)),2)&" "&CHOOSE(MONTH(DATE(2025,2,1)),"enero","febrero","marzo","abril","mayo","junio","julio","agosto","septiembre","octubre","noviembre","diciembre") -> 2025-02 febrero | B21: =SUMIFS(Colección!$L$2:$L$10001,Colección!$M$2:$M$10001,"Compra",Colección!$D$2:$D$10001,">="&DATE(2025,2,1),Colección!$D$2:$D$10001,"<"&DATE(2025,3,1)) -> 937.97 | J21: ="Cancelado" -> Cancelado | K21: =SUMIFS(Colección!$K$2:$K$10001,Colección!$M$2:$M$10001,$J21) -> 0 | L21: =IF($J21="Compra",SUMIFS(Colección!$L$2:$L$10001,Colección!$M$2:$M$10001,$J21),0) -> 0 | M21: =IF($J21="Venta",SUMIFS(Colección!$N$2:$N$10001,Colección!$M$2:$M$10001,$J21),0) -> 0
A22: =YEAR(DATE(2025,1,1))&"-"&RIGHT("0"&MONTH(DATE(2025,1,1)),2)&" "&CHOOSE(MONTH(DATE(2025,1,1)),"enero","febrero","marzo","abril","mayo","junio","julio","agosto","septiembre","octubre","noviembre","diciembre") -> 2025-01 enero | B22: =SUMIFS(Colección!$L$2:$L$10001,Colección!$M$2:$M$10001,"Compra",Colección!$D$2:$D$10001,">="&DATE(2025,1,1),Colección!$D$2:$D$10001,"<"&DATE(2025,2,1)) -> 562.59
A23: =YEAR(DATE(2024,12,1))&"-"&RIGHT("0"&MONTH(DATE(2024,12,1)),2)&" "&CHOOSE(MONTH(DATE(2024,12,1)),"enero","febrero","marzo","abril","mayo","junio","julio","agosto","septiembre","octubre","noviembre","diciembre") -> 2024-12 diciembre | B23: =SUMIFS(Colección!$L$2:$L$10001,Colección!$M$2:$M$10001,"Compra",Colección!$D$2:$D$10001,">="&DATE(2024,12,1),Colección!$D$2:$D$10001,"<"&DATE(2024,13,1)) -> 897.14
A24: =YEAR(DATE(2024,11,1))&"-"&RIGHT("0"&MONTH(DATE(2024,11,1)),2)&" "&CHOOSE(MONTH(DATE(2024,11,1)),"enero","febrero","marzo","abril","mayo","junio","julio","agosto","septiembre","octubre","noviembre","diciembre") -> 2024-11 noviembre | B24: =SUMIFS(Colección!$L$2:$L$10001,Colección!$M$2:$M$10001,"Compra",Colección!$D$2:$D$10001,">="&DATE(2024,11,1),Colección!$D$2:$D$10001,"<"&DATE(2024,12,1)) -> 583.05
A25: =YEAR(DATE(2024,10,1))&"-"&RIGHT("0"&MONTH(DATE(2024,10,1)),2)&" "&CHOOSE(MONTH(DATE(2024,10,1)),"enero","febrero","marzo","abril","mayo","junio","julio","agosto","septiembre","octubre","noviembre","diciembre") -> 2024-10 octubre | B25: =SUMIFS(Colección!$L$2:$L$10001,Colección!$M$2:$M$10001,"Compra",Colección!$D$2:$D$10001,">="&DATE(2024,10,1),Colección!$D$2:$D$10001,"<"&DATE(2024,11,1)) -> 800.76
A26: =YEAR(DATE(2024,9,1))&"-"&RIGHT("0"&MONTH(DATE(2024,9,1)),2)&" "&CHOOSE(MONTH(DATE(2024,9,1)),"enero","febrero","marzo","abril","mayo","junio","julio","agosto","septiembre","octubre","noviembre","diciembre") -> 2024-09 septiembre | B26: =SUMIFS(Colección!$L$2:$L$10001,Colección!$M$2:$M$10001,"Compra",Colección!$D$2:$D$10001,">="&DATE(2024,9,1),Colección!$D$2:$D$10001,"<"&DATE(2024,10,1)) -> 450.39
A27: =YEAR(DATE(2024,8,1))&"-"&RIGHT("0"&MONTH(DATE(2024,8,1)),2)&" "&CHOOSE(MONTH(DATE(2024,8,1)),"enero","febrero","marzo","abril","mayo","junio","julio","agosto","septiembre","octubre","noviembre","diciembre") -> 2024-08 agosto | B27: =SUMIFS(Colección!$L$2:$L$10001,Colección!$M$2:$M$10001,"Compra",Colección!$D$2:$D$10001,">="&DATE(2024,8,1),Colección!$D$2:$D$10001,"<"&DATE(2024,9,1)) -> 664.07
A28: =YEAR(DATE(2024,7,1))&"-"&RIGHT("0"&MONTH(DATE(2024,7,1)),2)&" "&CHOOSE(MONTH(DATE(2024,7,1)),"enero","febrero","marzo","abril","mayo","junio","julio","agosto","septiembre","octubre","noviembre","diciembre") -> 2024-07 julio | B28: =SUMIFS(Colección!$L$2:$L$10001,Colección!$M$2:$M$10001,"Compra",Colección!$D$2:$D$10001,">="&DATE(2024,7,1),Colección!$D$2:$D$10001,"<"&DATE(2024,8,1)) -> 1260.31
A29: =YEAR(DATE(2024,6,1))&"-"&RIGHT("0"&MONTH(DATE(2024,6,1)),2)&" "&CHOOSE(MONTH(DATE(2024,6,1)),"enero","febrero","marzo","abril","mayo","junio","julio","agosto","septiembre","octubre","noviembre","diciembre") -> 2024-06 junio | B29: =SUMIFS(Colección!$L$2:$L$10001,Colección!$M$2:$M$10001,"Compra",Colección!$D$2:$D$10001,">="&DATE(2024,6,1),Colección!$D$2:$D$10001,"<"&DATE(2024,7,1)) -> 2096.53
A30: =YEAR(DATE(2024,5,1))&"-"&RIGHT("0"&MONTH(DATE(2024,5,1)),2)&" "&CHOOSE(MONTH(DATE(2024,5,1)),"enero","febrero","marzo","abril","mayo","junio","julio","agosto","septiembre","octubre","noviembre","diciembre") -> 2024-05 mayo | B30: =SUMIFS(Colección!$L$2:$L$10001,Colección!$M$2:$M$10001,"Compra",Colección!$D$2:$D$10001,">="&DATE(2024,5,1),Colección!$D$2:$D$10001,"<"&DATE(2024,6,1)) -> 1971.47
A31: =YEAR(DATE(2024,4,1))&"-"&RIGHT("0"&MONTH(DATE(2024,4,1)),2)&" "&CHOOSE(MONTH(DATE(2024,4,1)),"enero","febrero","marzo","abril","mayo","junio","julio","agosto","septiembre","octubre","noviembre","diciembre") -> 2024-04 abril | B31: =SUMIFS(Colección!$L$2:$L$10001,Colección!$M$2:$M$10001,"Compra",Colección!$D$2:$D$10001,">="&DATE(2024,4,1),Colección!$D$2:$D$10001,"<"&DATE(2024,5,1)) -> 497.54
A32: =YEAR(DATE(2024,3,1))&"-"&RIGHT("0"&MONTH(DATE(2024,3,1)),2)&" "&CHOOSE(MONTH(DATE(2024,3,1)),"enero","febrero","marzo","abril","mayo","junio","julio","agosto","septiembre","octubre","noviembre","diciembre") -> 2024-03 marzo | B32: =SUMIFS(Colección!$L$2:$L$10001,Colección!$M$2:$M$10001,"Compra",Colección!$D$2:$D$10001,">="&DATE(2024,3,1),Colección!$D$2:$D$10001,"<"&DATE(2024,4,1)) -> 519.02
A33: =YEAR(DATE(2024,2,1))&"-"&RIGHT("0"&MONTH(DATE(2024,2,1)),2)&" "&CHOOSE(MONTH(DATE(2024,2,1)),"enero","febrero","marzo","abril","mayo","junio","julio","agosto","septiembre","octubre","noviembre","diciembre") -> 2024-02 febrero | B33: =SUMIFS(Colección!$L$2:$L$10001,Colección!$M$2:$M$10001,"Compra",Colección!$D$2:$D$10001,">="&DATE(2024,2,1),Colección!$D$2:$D$10001,"<"&DATE(2024,3,1)) -> 435.24 | J33: Top ediciones por gasto
A34: =YEAR(DATE(2024,1,1))&"-"&RIGHT("0"&MONTH(DATE(2024,1,1)),2)&" "&CHOOSE(MONTH(DATE(2024,1,1)),"enero","febrero","marzo","abril","mayo","junio","julio","agosto","septiembre","octubre","noviembre","diciembre") -> 2024-01 enero | B34: =SUMIFS(Colección!$L$2:$L$10001,Colección!$M$2:$M$10001,"Compra",Colección!$D$2:$D$10001,">="&DATE(2024,1,1),Colección!$D$2:$D$10001,"<"&DATE(2024,2,1)) -> 596.42 | J34: Edition | K34: Suma de Total | L34: Suma de Quantity
A35: =YEAR(DATE(2023,12,1))&"-"&RIGHT("0"&MONTH(DATE(2023,12,1)),2)&" "&CHOOSE(MONTH(DATE(2023,12,1)),"enero","febrero","marzo","abril","mayo","junio","julio","agosto","septiembre","octubre","noviembre","diciembre") -> 2023-12 diciembre | B35: =SUMIFS(Colección!$L$2:$L$10001,Colección!$M$2:$M$10001,"Compra",Colección!$D$2:$D$10001,">="&DATE(2023,12,1),Colección!$D$2:$D$10001,"<"&DATE(2023,13,1)) -> 1079.91 | J35: =IFERROR(INDEX('Aux Graficos'!$A$2:$A$321,MATCH(1,'Aux Graficos'!$D$2:$D$321,0)),"") -> Modern Horizons 2: Extras | K35: =IF($J35="","",SUMIFS(Colección!$L$2:$L$10001,Colección!$G$2:$G$10001,$J35,Colección!$M$2:$M$10001,"Compra")) -> 2246.7577 | L35: =IF($J35="","",SUMIFS(Colección!$K$2:$K$10001,Colección!$G$2:$G$10001,$J35,Colección!$M$2:$M$10001,"Compra")) -> 145
A36: =YEAR(DATE(2023,11,1))&"-"&RIGHT("0"&MONTH(DATE(2023,11,1)),2)&" "&CHOOSE(MONTH(DATE(2023,11,1)),"enero","febrero","marzo","abril","mayo","junio","julio","agosto","septiembre","octubre","noviembre","diciembre") -> 2023-11 noviembre | B36: =SUMIFS(Colección!$L$2:$L$10001,Colección!$M$2:$M$10001,"Compra",Colección!$D$2:$D$10001,">="&DATE(2023,11,1),Colección!$D$2:$D$10001,"<"&DATE(2023,12,1)) -> 361.7 | J36: =IFERROR(INDEX('Aux Graficos'!$A$2:$A$321,MATCH(2,'Aux Graficos'!$D$2:$D$321,0)),"") -> Unleashed | K36: =IF($J36="","",SUMIFS(Colección!$L$2:$L$10001,Colección!$G$2:$G$10001,$J36,Colección!$M$2:$M$10001,"Compra")) -> 1759.3655 | L36: =IF($J36="","",SUMIFS(Colección!$K$2:$K$10001,Colección!$G$2:$G$10001,$J36,Colección!$M$2:$M$10001,"Compra")) -> 163
A37: =YEAR(DATE(2023,10,1))&"-"&RIGHT("0"&MONTH(DATE(2023,10,1)),2)&" "&CHOOSE(MONTH(DATE(2023,10,1)),"enero","febrero","marzo","abril","mayo","junio","julio","agosto","septiembre","octubre","noviembre","diciembre") -> 2023-10 octubre | B37: =SUMIFS(Colección!$L$2:$L$10001,Colección!$M$2:$M$10001,"Compra",Colección!$D$2:$D$10001,">="&DATE(2023,10,1),Colección!$D$2:$D$10001,"<"&DATE(2023,11,1)) -> 487.02 | J37: =IFERROR(INDEX('Aux Graficos'!$A$2:$A$321,MATCH(3,'Aux Graficos'!$D$2:$D$321,0)),"") -> Modern Horizons 3 | K37: =IF($J37="","",SUMIFS(Colección!$L$2:$L$10001,Colección!$G$2:$G$10001,$J37,Colección!$M$2:$M$10001,"Compra")) -> 1489.2334 | L37: =IF($J37="","",SUMIFS(Colección!$K$2:$K$10001,Colección!$G$2:$G$10001,$J37,Colección!$M$2:$M$10001,"Compra")) -> 265
A38: =YEAR(DATE(2023,9,1))&"-"&RIGHT("0"&MONTH(DATE(2023,9,1)),2)&" "&CHOOSE(MONTH(DATE(2023,9,1)),"enero","febrero","marzo","abril","mayo","junio","julio","agosto","septiembre","octubre","noviembre","diciembre") -> 2023-09 septiembre | B38: =SUMIFS(Colección!$L$2:$L$10001,Colección!$M$2:$M$10001,"Compra",Colección!$D$2:$D$10001,">="&DATE(2023,9,1),Colección!$D$2:$D$10001,"<"&DATE(2023,10,1)) -> 424.94 | J38: =IFERROR(INDEX('Aux Graficos'!$A$2:$A$321,MATCH(4,'Aux Graficos'!$D$2:$D$321,0)),"") -> Exodus | K38: =IF($J38="","",SUMIFS(Colección!$L$2:$L$10001,Colección!$G$2:$G$10001,$J38,Colección!$M$2:$M$10001,"Compra")) -> 1327.3305 | L38: =IF($J38="","",SUMIFS(Colección!$K$2:$K$10001,Colección!$G$2:$G$10001,$J38,Colección!$M$2:$M$10001,"Compra")) -> 9
A39: =YEAR(DATE(2023,8,1))&"-"&RIGHT("0"&MONTH(DATE(2023,8,1)),2)&" "&CHOOSE(MONTH(DATE(2023,8,1)),"enero","febrero","marzo","abril","mayo","junio","julio","agosto","septiembre","octubre","noviembre","diciembre") -> 2023-08 agosto | B39: =SUMIFS(Colección!$L$2:$L$10001,Colección!$M$2:$M$10001,"Compra",Colección!$D$2:$D$10001,">="&DATE(2023,8,1),Colección!$D$2:$D$10001,"<"&DATE(2023,9,1)) -> 134.95 | J39: =IFERROR(INDEX('Aux Graficos'!$A$2:$A$321,MATCH(5,'Aux Graficos'!$D$2:$D$321,0)),"") -> Modern Horizons 3: Extras | K39: =IF($J39="","",SUMIFS(Colección!$L$2:$L$10001,Colección!$G$2:$G$10001,$J39,Colección!$M$2:$M$10001,"Compra")) -> 1316.4214 | L39: =IF($J39="","",SUMIFS(Colección!$K$2:$K$10001,Colección!$G$2:$G$10001,$J39,Colección!$M$2:$M$10001,"Compra")) -> 123
A40: =YEAR(DATE(2023,7,1))&"-"&RIGHT("0"&MONTH(DATE(2023,7,1)),2)&" "&CHOOSE(MONTH(DATE(2023,7,1)),"enero","febrero","marzo","abril","mayo","junio","julio","agosto","septiembre","octubre","noviembre","diciembre") -> 2023-07 julio | B40: =SUMIFS(Colección!$L$2:$L$10001,Colección!$M$2:$M$10001,"Compra",Colección!$D$2:$D$10001,">="&DATE(2023,7,1),Colección!$D$2:$D$10001,"<"&DATE(2023,8,1)) -> 1108.3936 | J40: =IFERROR(INDEX('Aux Graficos'!$A$2:$A$321,MATCH(6,'Aux Graficos'!$D$2:$D$321,0)),"") -> The Lord of the Rings: Tales of Middle-earth | K40: =IF($J40="","",SUMIFS(Colección!$L$2:$L$10001,Colección!$G$2:$G$10001,$J40,Colección!$M$2:$M$10001,"Compra")) -> 1260.9508 | L40: =IF($J40="","",SUMIFS(Colección!$K$2:$K$10001,Colección!$G$2:$G$10001,$J40,Colección!$M$2:$M$10001,"Compra")) -> 266
A41: =YEAR(DATE(2023,6,1))&"-"&RIGHT("0"&MONTH(DATE(2023,6,1)),2)&" "&CHOOSE(MONTH(DATE(2023,6,1)),"enero","febrero","marzo","abril","mayo","junio","julio","agosto","septiembre","octubre","noviembre","diciembre") -> 2023-06 junio | B41: =SUMIFS(Colección!$L$2:$L$10001,Colección!$M$2:$M$10001,"Compra",Colección!$D$2:$D$10001,">="&DATE(2023,6,1),Colección!$D$2:$D$10001,"<"&DATE(2023,7,1)) -> 334.72 | J41: =IFERROR(INDEX('Aux Graficos'!$A$2:$A$321,MATCH(7,'Aux Graficos'!$D$2:$D$321,0)),"") -> Urza's Saga | K41: =IF($J41="","",SUMIFS(Colección!$L$2:$L$10001,Colección!$G$2:$G$10001,$J41,Colección!$M$2:$M$10001,"Compra")) -> 1128.7762 | L41: =IF($J41="","",SUMIFS(Colección!$K$2:$K$10001,Colección!$G$2:$G$10001,$J41,Colección!$M$2:$M$10001,"Compra")) -> 71
...

Sheet Aux Graficos
A1: Edition | B1: Total compra | C1: Quantity compra | D1: Ranking | F1: Card Name | G1: Total compra | H1: Ranking | J1: Idioma | K1: Quantity compra | L1: Ranking
A2: ="2016 Version" -> 2016 Version | B2: =SUMIFS(Colección!$L$2:$L$10001,Colección!$G$2:$G$10001,$A2,Colección!$M$2:$M$10001,"Compra") -> 7.5830703 | C2: =SUMIFS(Colección!$K$2:$K$10001,Colección!$G$2:$G$10001,$A2,Colección!$M$2:$M$10001,"Compra") -> 2 | D2: =IF($B2=0,"",_xlfn.RANK.EQ($B2,$B$2:$B$321,0)+COUNTIF($B$2:B2,$B2)-1) -> 245 | F2: ="10 Ultimate Guard Dividers" -> 10 Ultimate Guard Dividers | G2: =SUMIFS(Colección!$L$2:$L$10001,Colección!$F$2:$F$10001,$F2,Colección!$M$2:$M$10001,"Compra") -> 1.9424487 | H2: =IF($G2=0,"",_xlfn.RANK.EQ($G2,$G$2:$G$2353,0)+COUNTIF($G$2:G2,$G2)-1) -> 1382 | J2: ="Alemán" -> Alemán | K2: =SUMIFS(Colección!$K$2:$K$10001,Colección!$I$2:$I$10001,$J2,Colección!$M$2:$M$10001,"Compra") -> 3 | L2: =IF($K2=0,"",_xlfn.RANK.EQ($K2,$K$2:$K$11,0)+COUNTIF($K$2:K2,$K2)-1) -> 9 | P2: =ORDENAR(UNICOS(FILTRAR(Colección[Edición];Colección[Edición]<>""))) | Q2: =ORDENAR(UNICOS(FILTRAR(Colección[Carta];Colección[Carta]<>""))) | R2: =ORDENAR(UNICOS(FILTRAR(Colección[Idioma];Colección[Idioma]<>"")))
A3: ="30th Anniversary Celebration" -> 30th Anniversary Celebration | B3: =SUMIFS(Colección!$L$2:$L$10001,Colección!$G$2:$G$10001,$A3,Colección!$M$2:$M$10001,"Compra") -> 5.5532001 | C3: =SUMIFS(Colección!$K$2:$K$10001,Colección!$G$2:$G$10001,$A3,Colección!$M$2:$M$10001,"Compra") -> 3 | D3: =IF($B3=0,"",_xlfn.RANK.EQ($B3,$B$2:$B$321,0)+COUNTIF($B$2:B3,$B3)-1) -> 262 | F3: ="100 Dragon Shield Sleeves" -> 100 Dragon Shield Sleeves | G3: =SUMIFS(Colección!$L$2:$L$10001,Colección!$F$2:$F$10001,$F3,Colección!$M$2:$M$10001,"Compra") -> 118.05668 | H3: =IF($G3=0,"",_xlfn.RANK.EQ($G3,$G$2:$G$2353,0)+COUNTIF($G$2:G3,$G3)-1) -> 59 | J3: ="Chino" -> Chino | K3: =SUMIFS(Colección!$K$2:$K$10001,Colección!$I$2:$I$10001,$J3,Colección!$M$2:$M$10001,"Compra") -> 5 | L3: =IF($K3=0,"",_xlfn.RANK.EQ($K3,$K$2:$K$11,0)+COUNTIF($K$2:K3,$K3)-1) -> 7
A4: ="Accesorios" -> Accesorios | B4: =SUMIFS(Colección!$L$2:$L$10001,Colección!$G$2:$G$10001,$A4,Colección!$M$2:$M$10001,"Compra") -> 252.84478 | C4: =SUMIFS(Colección!$K$2:$K$10001,Colección!$G$2:$G$10001,$A4,Colección!$M$2:$M$10001,"Compra") -> 51 | D4: =IF($B4=0,"",_xlfn.RANK.EQ($B4,$B$2:$B$321,0)+COUNTIF($B$2:B4,$B4)-1) -> 34 | F4: ="100 Gamegenic Just Sleeves Inner Sleeves" -> 100 Gamegenic Just Sleeves Inner Sleeves | G4: =SUMIFS(Colección!$L$2:$L$10001,Colección!$F$2:$F$10001,$F4,Colección!$M$2:$M$10001,"Compra") -> 14.31 | H4: =IF($G4=0,"",_xlfn.RANK.EQ($G4,$G$2:$G$2353,0)+COUNTIF($G$2:G4,$G4)-1) -> 521 | J4: ="Chino-S" -> Chino-S | K4: =SUMIFS(Colección!$K$2:$K$10001,Colección!$I$2:$I$10001,$J4,Colección!$M$2:$M$10001,"Compra") -> 64 | L4: =IF($K4=0,"",_xlfn.RANK.EQ($K4,$K$2:$K$11,0)+COUNTIF($K$2:K4,$K4)-1) -> 4
A5: ="Adventures in the Forgotten Realms" -> Adventures in the Forgotten Realms | B5: =SUMIFS(Colección!$L$2:$L$10001,Colección!$G$2:$G$10001,$A5,Colección!$M$2:$M$10001,"Compra") -> 74.958987 | C5: =SUMIFS(Colección!$K$2:$K$10001,Colección!$G$2:$G$10001,$A5,Colección!$M$2:$M$10001,"Compra") -> 35 | D5: =IF($B5=0,"",_xlfn.RANK.EQ($B5,$B$2:$B$321,0)+COUNTIF($B$2:B5,$B5)-1) -> 111 | F5: ="100 KMC Perfect Sized Sleeves" -> 100 KMC Perfect Sized Sleeves | G5: =SUMIFS(Colección!$L$2:$L$10001,Colección!$F$2:$F$10001,$F5,Colección!$M$2:$M$10001,"Compra") -> 65.014889 | H5: =IF($G5=0,"",_xlfn.RANK.EQ($G5,$G$2:$G$2353,0)+COUNTIF($G$2:G5,$G5)-1) -> 128 | J5: ="Chino-T" -> Chino-T | K5: =SUMIFS(Colección!$K$2:$K$10001,Colección!$I$2:$I$10001,$J5,Colección!$M$2:$M$10001,"Compra") -> 6 | L5: =IF($K5=0,"",_xlfn.RANK.EQ($K5,$K$2:$K$11,0)+COUNTIF($K$2:K5,$K5)-1) -> 6
A6: ="Adventures in the Forgotten Realms: Extras" -> Adventures in the Forgotten Realms: Extras | B6: =SUMIFS(Colección!$L$2:$L$10001,Colección!$G$2:$G$10001,$A6,Colección!$M$2:$M$10001,"Compra") -> 21.442508 | C6: =SUMIFS(Colección!$K$2:$K$10001,Colección!$G$2:$G$10001,$A6,Colección!$M$2:$M$10001,"Compra") -> 4 | D6: =IF($B6=0,"",_xlfn.RANK.EQ($B6,$B$2:$B$321,0)+COUNTIF($B$2:B6,$B6)-1) -> 202 | F6: ="100 Ultra Pro PLATINUM Nine Pocket Pages" -> 100 Ultra Pro PLATINUM Nine Pocket Pages | G6: =SUMIFS(Colección!$L$2:$L$10001,Colección!$F$2:$F$10001,$F6,Colección!$M$2:$M$10001,"Compra") -> 22.57773 | H6: =IF($G6=0,"",_xlfn.RANK.EQ($G6,$G$2:$G$2353,0)+COUNTIF($G$2:G6,$G6)-1) -> 347 | J6: ="Español" -> Español | K6: =SUMIFS(Colección!$K$2:$K$10001,Colección!$I$2:$I$10001,$J6,Colección!$M$2:$M$10001,"Compra") -> 451 | L6: =IF($K6=0,"",_xlfn.RANK.EQ($K6,$K$2:$K$11,0)+COUNTIF($K$2:K6,$K6)-1) -> 3
A7: ="Adventures in the Forgotten Realms: Promos" -> Adventures in the Forgotten Realms: Promos | B7: =SUMIFS(Colección!$L$2:$L$10001,Colección!$G$2:$G$10001,$A7,Colección!$M$2:$M$10001,"Compra") -> 1.6484393 | C7: =SUMIFS(Colección!$K$2:$K$10001,Colección!$G$2:$G$10001,$A7,Colección!$M$2:$M$10001,"Compra") -> 1 | D7: =IF($B7=0,"",_xlfn.RANK.EQ($B7,$B$2:$B$321,0)+COUNTIF($B$2:B7,$B7)-1) -> 292 | F7: ="Abandon" -> Abandon | G7: =SUMIFS(Colección!$L$2:$L$10001,Colección!$F$2:$F$10001,$F7,Colección!$M$2:$M$10001,"Compra") -> 9.2493671 | H7: =IF($G7=0,"",_xlfn.RANK.EQ($G7,$G$2:$G$2353,0)+COUNTIF($G$2:G7,$G7)-1) -> 691 | J7: ="Francés" -> Francés | K7: =SUMIFS(Colección!$K$2:$K$10001,Colección!$I$2:$I$10001,$J7,Colección!$M$2:$M$10001,"Compra") -> 4 | L7: =IF($K7=0,"",_xlfn.RANK.EQ($K7,$K$2:$K$11,0)+COUNTIF($K$2:K7,$K7)-1) -> 8
A8: ="Aether Revolt" -> Aether Revolt | B8: =SUMIFS(Colección!$L$2:$L$10001,Colección!$G$2:$G$10001,$A8,Colección!$M$2:$M$10001,"Compra") -> 201.79916 | C8: =SUMIFS(Colección!$K$2:$K$10001,Colección!$G$2:$G$10001,$A8,Colección!$M$2:$M$10001,"Compra") -> 24 | D8: =IF($B8=0,"",_xlfn.RANK.EQ($B8,$B$2:$B$321,0)+COUNTIF($B$2:B8,$B8)-1) -> 48 | F8: ="Abandon Attachments" -> Abandon Attachments | G8: =SUMIFS(Colección!$L$2:$L$10001,Colección!$F$2:$F$10001,$F8,Colección!$M$2:$M$10001,"Compra") -> 1.1789474 | H8: =IF($G8=0,"",_xlfn.RANK.EQ($G8,$G$2:$G$2353,0)+COUNTIF($G$2:G8,$G8)-1) -> 1569 | J8: ="Inglés" -> Inglés | K8: =SUMIFS(Colección!$K$2:$K$10001,Colección!$I$2:$I$10001,$J8,Colección!$M$2:$M$10001,"Compra") -> 5499 | L8: =IF($K8=0,"",_xlfn.RANK.EQ($K8,$K$2:$K$11,0)+COUNTIF($K$2:K8,$K8)-1) -> 1
A9: ="Aetherdrift" -> Aetherdrift | B9: =SUMIFS(Colección!$L$2:$L$10001,Colección!$G$2:$G$10001,$A9,Colección!$M$2:$M$10001,"Compra") -> 94.200366 | C9: =SUMIFS(Colección!$K$2:$K$10001,Colección!$G$2:$G$10001,$A9,Colección!$M$2:$M$10001,"Compra") -> 66 | D9: =IF($B9=0,"",_xlfn.RANK.EQ($B9,$B$2:$B$321,0)+COUNTIF($B$2:B9,$B9)-1) -> 86 | F9: ="Abandoned Hall" -> Abandoned Hall | G9: =SUMIFS(Colección!$L$2:$L$10001,Colección!$F$2:$F$10001,$F9,Colección!$M$2:$M$10001,"Compra") -> 0.64365654 | H9: =IF($G9=0,"",_xlfn.RANK.EQ($G9,$G$2:$G$2353,0)+COUNTIF($G$2:G9,$G9)-1) -> 1793 | J9: ="Italiano" -> Italiano | K9: =SUMIFS(Colección!$K$2:$K$10001,Colección!$I$2:$I$10001,$J9,Colección!$M$2:$M$10001,"Compra") -> 8 | L9: =IF($K9=0,"",_xlfn.RANK.EQ($K9,$K$2:$K$11,0)+COUNTIF($K$2:K9,$K9)-1) -> 5
A10: ="Aetherdrift: Extras" -> Aetherdrift: Extras | B10: =SUMIFS(Colección!$L$2:$L$10001,Colección!$G$2:$G$10001,$A10,Colección!$M$2:$M$10001,"Compra") -> 363.38989 | C10: =SUMIFS(Colección!$K$2:$K$10001,Colección!$G$2:$G$10001,$A10,Colección!$M$2:$M$10001,"Compra") -> 40 | D10: =IF($B10=0,"",_xlfn.RANK.EQ($B10,$B$2:$B$321,0)+COUNTIF($B$2:B10,$B10)-1) -> 22 | F10: ="Abhorrent Oculus" -> Abhorrent Oculus | G10: =SUMIFS(Colección!$L$2:$L$10001,Colección!$F$2:$F$10001,$F10,Colección!$M$2:$M$10001,"Compra") -> 65.07 | H10: =IF($G10=0,"",_xlfn.RANK.EQ($G10,$G$2:$G$2353,0)+COUNTIF($G$2:G10,$G10)-1) -> 126 | J10: ="Japonés" -> Japonés | K10: =SUMIFS(Colección!$K$2:$K$10001,Colección!$I$2:$I$10001,$J10,Colección!$M$2:$M$10001,"Compra") -> 1098 | L10: =IF($K10=0,"",_xlfn.RANK.EQ($K10,$K$2:$K$11,0)+COUNTIF($K$2:K10,$K10)-1) -> 2
A11: ="Alara Reborn" -> Alara Reborn | B11: =SUMIFS(Colección!$L$2:$L$10001,Colección!$G$2:$G$10001,$A11,Colección!$M$2:$M$10001,"Compra") -> 27.5 | C11: =SUMIFS(Colección!$K$2:$K$10001,Colección!$G$2:$G$10001,$A11,Colección!$M$2:$M$10001,"Compra") -> 9 | D11: =IF($B11=0,"",_xlfn.RANK.EQ($B11,$B$2:$B$321,0)+COUNTIF($B$2:B11,$B11)-1) -> 181 | F11: ="Abrupt Decay" -> Abrupt Decay | G11: =SUMIFS(Colección!$L$2:$L$10001,Colección!$F$2:$F$10001,$F11,Colección!$M$2:$M$10001,"Compra") -> 12.707967 | H11: =IF($G11=0,"",_xlfn.RANK.EQ($G11,$G$2:$G$2353,0)+COUNTIF($G$2:G11,$G11)-1) -> 559 | J11: ="Ruso" -> Ruso | K11: =SUMIFS(Colección!$K$2:$K$10001,Colección!$I$2:$I$10001,$J11,Colección!$M$2:$M$10001,"Compra") -> 1 | L11: =IF($K11=0,"",_xlfn.RANK.EQ($K11,$K$2:$K$11,0)+COUNTIF($K$2:K11,$K11)-1) -> 10
A12: ="Alliances" -> Alliances | B12: =SUMIFS(Colección!$L$2:$L$10001,Colección!$G$2:$G$10001,$A12,Colección!$M$2:$M$10001,"Compra") -> 220.32818 | C12: =SUMIFS(Colección!$K$2:$K$10001,Colección!$G$2:$G$10001,$A12,Colección!$M$2:$M$10001,"Compra") -> 6 | D12: =IF($B12=0,"",_xlfn.RANK.EQ($B12,$B$2:$B$321,0)+COUNTIF($B$2:B12,$B12)-1) -> 44 | F12: ="Absorb" -> Absorb | G12: =SUMIFS(Colección!$L$2:$L$10001,Colección!$F$2:$F$10001,$F12,Colección!$M$2:$M$10001,"Compra") -> 1.5463706 | H12: =IF($G12=0,"",_xlfn.RANK.EQ($G12,$G$2:$G$2353,0)+COUNTIF($G$2:G12,$G12)-1) -> 1477
A13: ="Amber" -> Amber | B13: =SUMIFS(Colección!$L$2:$L$10001,Colección!$G$2:$G$10001,$A13,Colección!$M$2:$M$10001,"Compra") -> 7.2648649 | C13: =SUMIFS(Colección!$K$2:$K$10001,Colección!$G$2:$G$10001,$A13,Colección!$M$2:$M$10001,"Compra") -> 1 | D13: =IF($B13=0,"",_xlfn.RANK.EQ($B13,$B$2:$B$321,0)+COUNTIF($B$2:B13,$B13)-1) -> 247 | F13: ="Abstergo Entertainment (V.1)" -> Abstergo Entertainment (V.1) | G13: =SUMIFS(Colección!$L$2:$L$10001,Colección!$F$2:$F$10001,$F13,Colección!$M$2:$M$10001,"Compra") -> 1.6299891 | H13: =IF($G13=0,"",_xlfn.RANK.EQ($G13,$G$2:$G$2353,0)+COUNTIF($G$2:G13,$G13)-1) -> 1455
A14: ="Amethyst" -> Amethyst | B14: =SUMIFS(Colección!$L$2:$L$10001,Colección!$G$2:$G$10001,$A14,Colección!$M$2:$M$10001,"Compra") -> 7.7512531 | C14: =SUMIFS(Colección!$K$2:$K$10001,Colección!$G$2:$G$10001,$A14,Colección!$M$2:$M$10001,"Compra") -> 1 | D14: =IF($B14=0,"",_xlfn.RANK.EQ($B14,$B$2:$B$321,0)+COUNTIF($B$2:B14,$B14)-1) -> 244 | F14: ="Abundant Growth" -> Abundant Growth | G14: =SUMIFS(Colección!$L$2:$L$10001,Colección!$F$2:$F$10001,$F14,Colección!$M$2:$M$10001,"Compra") -> 5.729429 | H14: =IF($G14=0,"",_xlfn.RANK.EQ($G14,$G$2:$G$2353,0)+COUNTIF($G$2:G14,$G14)-1) -> 910
A15: ="Amonkhet" -> Amonkhet | B15: =SUMIFS(Colección!$L$2:$L$10001,Colección!$G$2:$G$10001,$A15,Colección!$M$2:$M$10001,"Compra") -> 22.213681 | C15: =SUMIFS(Colección!$K$2:$K$10001,Colección!$G$2:$G$10001,$A15,Colección!$M$2:$M$10001,"Compra") -> 26 | D15: =IF($B15=0,"",_xlfn.RANK.EQ($B15,$B$2:$B$321,0)+COUNTIF($B$2:B15,$B15)-1) -> 199 | F15: ="Abundant Growth (V.2)" -> Abundant Growth (V.2) | G15: =SUMIFS(Colección!$L$2:$L$10001,Colección!$F$2:$F$10001,$F15,Colección!$M$2:$M$10001,"Compra") -> 1.8881226 | H15: =IF($G15=0,"",_xlfn.RANK.EQ($G15,$G$2:$G$2353,0)+COUNTIF($G$2:G15,$G15)-1) -> 1388
A16: ="Apocalypse" -> Apocalypse | B16: =SUMIFS(Colección!$L$2:$L$10001,Colección!$G$2:$G$10001,$A16,Colección!$M$2:$M$10001,"Compra") -> 190.08716 | C16: =SUMIFS(Colección!$K$2:$K$10001,Colección!$G$2:$G$10001,$A16,Colección!$M$2:$M$10001,"Compra") -> 34 | D16: =IF($B16=0,"",_xlfn.RANK.EQ($B16,$B$2:$B$321,0)+COUNTIF($B$2:B16,$B16)-1) -> 50 | F16: ="Abundant Harvest" -> Abundant Harvest | G16: =SUMIFS(Colección!$L$2:$L$10001,Colección!$F$2:$F$10001,$F16,Colección!$M$2:$M$10001,"Compra") -> 0.45013193 | H16: =IF($G16=0,"",_xlfn.RANK.EQ($G16,$G$2:$G$2353,0)+COUNTIF($G$2:G16,$G16)-1) -> 1915
A17: ="Avacyn Restored" -> Avacyn Restored | B17: =SUMIFS(Colección!$L$2:$L$10001,Colección!$G$2:$G$10001,$A17,Colección!$M$2:$M$10001,"Compra") -> 155.46771 | C17: =SUMIFS(Colección!$K$2:$K$10001,Colección!$G$2:$G$10001,$A17,Colección!$M$2:$M$10001,"Compra") -> 16 | D17: =IF($B17=0,"",_xlfn.RANK.EQ($B17,$B$2:$B$321,0)+COUNTIF($B$2:B17,$B17)-1) -> 63 | F17: ="Academy Manufactor [Playset]" -> Academy Manufactor [Playset] | G17: =SUMIFS(Colección!$L$2:$L$10001,Colección!$F$2:$F$10001,$F17,Colección!$M$2:$M$10001,"Compra") -> 12.18 | H17: =IF($G17=0,"",_xlfn.RANK.EQ($G17,$G$2:$G$2353,0)+COUNTIF($G$2:G17,$G17)-1) -> 572
A18: ="Avatar: The Last Airbender" -> Avatar: The Last Airbender | B18: =SUMIFS(Colección!$L$2:$L$10001,Colección!$G$2:$G$10001,$A18,Colección!$M$2:$M$10001,"Compra") -> 0.28942308 | C18: =SUMIFS(Colección!$K$2:$K$10001,Colección!$G$2:$G$10001,$A18,Colección!$M$2:$M$10001,"Compra") -> 1 | D18: =IF($B18=0,"",_xlfn.RANK.EQ($B18,$B$2:$B$321,0)+COUNTIF($B$2:B18,$B18)-1) -> 310 | F18: ="Acceptable Losses" -> Acceptable Losses | G18: =SUMIFS(Colección!$L$2:$L$10001,Colección!$F$2:$F$10001,$F18,Colección!$M$2:$M$10001,"Compra") -> 3.6077508 | H18: =IF($G18=0,"",_xlfn.RANK.EQ($G18,$G$2:$G$2353,0)+COUNTIF($G$2:G18,$G18)-1) -> 1103
A19: ="Awakening of the New Era" -> Awakening of the New Era | B19: =SUMIFS(Colección!$L$2:$L$10001,Colección!$G$2:$G$10001,$A19,Colección!$M$2:$M$10001,"Compra") -> 97.457608 | C19: =SUMIFS(Colección!$K$2:$K$10001,Colección!$G$2:$G$10001,$A19,Colección!$M$2:$M$10001,"Compra") -> 120 | D19: =IF($B19=0,"",_xlfn.RANK.EQ($B19,$B$2:$B$321,0)+COUNTIF($B$2:B19,$B19)-1) -> 84 | F19: ="Accumulate Wisdom" -> Accumulate Wisdom | G19: =SUMIFS(Colección!$L$2:$L$10001,Colección!$F$2:$F$10001,$F19,Colección!$M$2:$M$10001,"Compra") -> 4.4210526 | H19: =IF($G19=0,"",_xlfn.RANK.EQ($G19,$G$2:$G$2353,0)+COUNTIF($G$2:G19,$G19)-1) -> 1007
A20: ="Battle for Zendikar" -> Battle for Zendikar | B20: =SUMIFS(Colección!$L$2:$L$10001,Colección!$G$2:$G$10001,$A20,Colección!$M$2:$M$10001,"Compra") -> 89.314353 | C20: =SUMIFS(Colección!$K$2:$K$10001,Colección!$G$2:$G$10001,$A20,Colección!$M$2:$M$10001,"Compra") -> 18 | D20: =IF($B20=0,"",_xlfn.RANK.EQ($B20,$B$2:$B$321,0)+COUNTIF($B$2:B20,$B20)-1) -> 93 | F20: ="Accumulated Knowledge" -> Accumulated Knowledge | G20: =SUMIFS(Colección!$L$2:$L$10001,Colección!$F$2:$F$10001,$F20,Colección!$M$2:$M$10001,"Compra") -> 7.5 | H20: =IF($G20=0,"",_xlfn.RANK.EQ($G20,$G$2:$G$2353,0)+COUNTIF($G$2:G20,$G20)-1) -> 774
A21: ="Betrayers of Kamigawa" -> Betrayers of Kamigawa | B21: =SUMIFS(Colección!$L$2:$L$10001,Colección!$G$2:$G$10001,$A21,Colección!$M$2:$M$10001,"Compra") -> 78.78963 | C21: =SUMIFS(Colección!$K$2:$K$10001,Colección!$G$2:$G$10001,$A21,Colección!$M$2:$M$10001,"Compra") -> 13 | D21: =IF($B21=0,"",_xlfn.RANK.EQ($B21,$B$2:$B$321,0)+COUNTIF($B$2:B21,$B21)-1) -> 105 | F21: ="Accursed Marauder (V.1)" -> Accursed Marauder (V.1) | G21: =SUMIFS(Colección!$L$2:$L$10001,Colección!$F$2:$F$10001,$F21,Colección!$M$2:$M$10001,"Compra") -> 1.8419022 | H21: =IF($G21=0,"",_xlfn.RANK.EQ($G21,$G$2:$G$2353,0)+COUNTIF($G$2:G21,$G21)-1) -> 1392
A22: ="Black" -> Black | B22: =SUMIFS(Colección!$L$2:$L$10001,Colección!$G$2:$G$10001,$A22,Colección!$M$2:$M$10001,"Compra") -> 15.892449 | C22: =SUMIFS(Colección!$K$2:$K$10001,Colección!$G$2:$G$10001,$A22,Colección!$M$2:$M$10001,"Compra") -> 2 | D22: =IF($B22=0,"",_xlfn.RANK.EQ($B22,$B$2:$B$321,0)+COUNTIF($B$2:B22,$B22)-1) -> 218 | F22: ="Aclazotz, Deepest Betrayal // Temple of the Dead" -> Aclazotz, Deepest Betrayal // Temple of the Dead | G22: =SUMIFS(Colección!$L$2:$L$10001,Colección!$F$2:$F$10001,$F22,Colección!$M$2:$M$10001,"Compra") -> 3.74 | H22: =IF($G22=0,"",_xlfn.RANK.EQ($G22,$G$2:$G$2353,0)+COUNTIF($G$2:G22,$G22)-1) -> 1088
A23: ="Bloomburrow" -> Bloomburrow | B23: =SUMIFS(Colección!$L$2:$L$10001,Colección!$G$2:$G$10001,$A23,Colección!$M$2:$M$10001,"Compra") -> 229.5508 | C23: =SUMIFS(Colección!$K$2:$K$10001,Colección!$G$2:$G$10001,$A23,Colección!$M$2:$M$10001,"Compra") -> 73 | D23: =IF($B23=0,"",_xlfn.RANK.EQ($B23,$B$2:$B$321,0)+COUNTIF($B$2:B23,$B23)-1) -> 42 | F23: ="Adaptatron" -> Adaptatron | G23: =SUMIFS(Colección!$L$2:$L$10001,Colección!$F$2:$F$10001,$F23,Colección!$M$2:$M$10001,"Compra") -> 5.8102456 | H23: =IF($G23=0,"",_xlfn.RANK.EQ($G23,$G$2:$G$2353,0)+COUNTIF($G$2:G23,$G23)-1) -> 901
A24: ="Bloomburrow: Extras" -> Bloomburrow: Extras | B24: =SUMIFS(Colección!$L$2:$L$10001,Colección!$G$2:$G$10001,$A24,Colección!$M$2:$M$10001,"Compra") -> 158.111 | C24: =SUMIFS(Colección!$K$2:$K$10001,Colección!$G$2:$G$10001,$A24,Colección!$M$2:$M$10001,"Compra") -> 25 | D24: =IF($B24=0,"",_xlfn.RANK.EQ($B24,$B$2:$B$321,0)+COUNTIF($B$2:B24,$B24)-1) -> 61 | F24: ="Adarkar Wastes" -> Adarkar Wastes | G24: =SUMIFS(Colección!$L$2:$L$10001,Colección!$F$2:$F$10001,$F24,Colección!$M$2:$M$10001,"Compra") -> 28.654545 | H24: =IF($G24=0,"",_xlfn.RANK.EQ($G24,$G$2:$G$2353,0)+COUNTIF($G$2:G24,$G24)-1) -> 286
A25: ="Bloomburrow: Tokens" -> Bloomburrow: Tokens | B25: =SUMIFS(Colección!$L$2:$L$10001,Colección!$G$2:$G$10001,$A25,Colección!$M$2:$M$10001,"Compra") -> 2.4070833 | C25: =SUMIFS(Colección!$K$2:$K$10001,Colección!$G$2:$G$10001,$A25,Colección!$M$2:$M$10001,"Compra") -> 4 | D25: =IF($B25=0,"",_xlfn.RANK.EQ($B25,$B$2:$B$321,0)+COUNTIF($B$2:B25,$B25)-1) -> 279 | F25: ="Adio (OP03-002)" -> Adio (OP03-002) | G25: =SUMIFS(Colección!$L$2:$L$10001,Colección!$F$2:$F$10001,$F25,Colección!$M$2:$M$10001,"Compra") -> 0.2855814 | H25: =IF($G25=0,"",_xlfn.RANK.EQ($G25,$G$2:$G$2353,0)+COUNTIF($G$2:G25,$G25)-1) -> 2006
A26: ="Buy a Box Promos" -> Buy a Box Promos | B26: =SUMIFS(Colección!$L$2:$L$10001,Colección!$G$2:$G$10001,$A26,Colección!$M$2:$M$10001,"Compra") -> 30.549471 | C26: =SUMIFS(Colección!$K$2:$K$10001,Colección!$G$2:$G$10001,$A26,Colección!$M$2:$M$10001,"Compra") -> 7 | D26: =IF($B26=0,"",_xlfn.RANK.EQ($B26,$B$2:$B$321,0)+COUNTIF($B$2:B26,$B26)-1) -> 174 | F26: ="Aether Hub" -> Aether Hub | G26: =SUMIFS(Colección!$L$2:$L$10001,Colección!$F$2:$F$10001,$F26,Colección!$M$2:$M$10001,"Compra") -> 3.316609 | H26: =IF($G26=0,"",_xlfn.RANK.EQ($G26,$G$2:$G$2353,0)+COUNTIF($G$2:G26,$G26)-1) -> 1147
